<mujoco model="plane arm">
    <!--  Copyright © 2018, Roboti LLC

          This file is licensed under the MuJoCo Resource License (the "License").
          You may not use this file except in compliance with the License.
          You may obtain a copy of the License at

            https://www.roboti.us/resourcelicense.txt
    -->

    <option timestep="0.005" iterations="50" solver="Newton" tolerance="1e-10"/>

    <!-- <size njmax="50" nconmax="10" nstack="200"/> -->

    <visual>
        <rgba haze=".3 .3 .3 1"/>
    </visual>

    <default>
        <joint type="hinge" pos="0 0 0" axis="0 0 1" damping="0.0"/>
    </default>

    <asset>
        <texture type="skybox" builtin="gradient" rgb1="0.6 0.6 0.6" rgb2="0 0 0" width="512" height="512"/> 

        <texture name="texplane" type="2d" builtin="checker" rgb1=".25 .25 .25" rgb2=".3 .3 .3" width="512" height="512" mark="cross" markrgb=".8 .8 .8"/>  

        <material name="matplane" reflectance="0.3" texture="texplane" texrepeat="1 1" texuniform="true"/>
    </asset>

    <worldbody>
        <geom name="floor" pos="0 0 -0.5" size="0 0 1" type="plane" material="matplane"/>

        <light directional="true" diffuse=".8 .8 .8" specular=".2 .2 .2" pos="0 0 5" dir="0 0 -1" />

        <body name="link0" pos="0 0 0">
            <geom name="link0" type="capsule" size="0.035" fromto="0 0 0  0.5 0 0" rgba=".5 .1 .1 1" group="1" contype="2" conaffinity="2"/>
            <joint name="joint0"/>

            <body name="link1" pos="0.5 0 0">
                <geom name="link1" type="capsule" size="0.035" fromto="0 0 0  0.5 0 0" rgba=".1 .5 .1 1" group="1" contype="4" conaffinity="4"/>
                <joint name="joint1"/>
                <body name="link2" pos="0.5 0 0">
                    <geom name="link2" type="capsule" size="0.035" fromto="0 0 0  0.5 0 0" rgba=".1 .1 .5 1" group="1" contype="8" conaffinity="8"/>
                    <joint name="joint2"/>
                    <body name="link3" pos="0.5 0 0">
                        <geom name="link3" type="capsule" size="0.035" fromto="0 0 0  0.5 0 0" rgba=".1 .3 .3 1" group="1" contype="16" conaffinity="16"/>
                        <joint name="joint3"/>
                        <body name="link4" pos="0.5 0 0">
                            <geom name="link4" type="capsule" size="0.035" fromto="0 0 0  0.5 0 0" rgba=".3 .1 .3 1" group="1" contype="32" conaffinity="32"/>
                            <joint name="joint4"/>
                            <body name="EE" pos="0.5 0 0">
                                <geom name="EE" type="sphere" size="0.045" rgba=".76 .76 .17 1" group="1"/>
                            </body>
                        </body>
                    </body>
                </body>
            </body>
        </body>
    </worldbody>

    <actuator>
        <motor name="joint0_motor" joint="joint0"/>
        <motor name="joint1_motor" joint="joint1"/>
        <motor name="joint2_motor" joint="joint2"/>
        <motor name="joint3_motor" joint="joint3"/>
        <motor name="joint4_motor" joint="joint4"/>

    </actuator>
</mujoco>
